Workbook

Sheet OPTIONAL
A1: OPTIONAL
A3: GRADE 1
A4: Graphs | B4: Unit 1A: Lists and Tables | C4: 1.1 Making, reading and interpreting lists and tables | D4: PINE_G1_C14_P1.1.1 | E4: Ch 14 Practice 1.1.1: Making lists | F4: To present data in lists and tables
D5: PINE_G1_C14_P1.1.2 | E5: Ch 14 Practice 1.1.2: Reading and interpreting lists | F5: To read and interpret lists and tables
D6: PINE_G1_C14_P1.1.3 | E6: Ch 14 Practice 1.1.3: Making tables | F6: To present data in lists and tables
D7: PINE_G1_C14_P1.1.4 | E7: Ch 14 Practice 1.1.4: Reading and interpreting tables | F7: To read and interpret lists and tables
A8: Mental Strategies | B8: Unit 1: Number Bonds | C8: 1.1 Pairing 1-digit numbers | D8: PINE_G2_C09_P1.1.1 | E8: Ch 9 Practice 1.1.1: Pairing 1-digit numbers | F8: To find pairs of 1-digit numbers with a total up to 18 and write the addition and subtraction facts for each number pair | G8: M1AL-IIIh-8 | H8: Patterns and Algebra | I8: constructs equivalent number expression using addition and subtraction.
D9: PINE_G2_C09_P1.1.2 | E9: Ch 9 Practice 1.1.2: Finding the missing part in an addition sentence | F9: To find the missing part in an addition sentence | G9: M1AL-IIIh-8 | H9: Patterns and Algebra | I9: constructs equivalent number expression using addition and subtraction.
D10: PINE_G2_C09_P1.1.3 | E10: Ch 9 Practice 1.1.3: Finding the missing part or whole in a subtraction sentence | F10: To find the missing part or whole in a subtraction sentence | G10: M1AL-IIIh-8 | H10: Patterns and Algebra | I10: constructs equivalent number expression using addition and subtraction.
D11: PINE_G2_C09_P1.1.4 | E11: Ch 9 Practice 1.1.4: Representing equality | F11: To use the = sign to represent equality, e.g. 16 + 4 = 17 + 3 | G11: M1AL-IIIh-8 | H11: Patterns and Algebra | I11: constructs equivalent number expression using addition and subtraction.
A12: Multiplication | B12: Unit 1: Adding Equal Groups | C12: 1.1 Adding the same number | F12: To recognize equal groups and find the total number in the groups by repeated addition To add equal groups using number lines | G12: M1NS-IIIa-37 | H12: Numbers and Number sense | I12: counts groups of equal quantity using concrete objects up to 50 and writes an equivalent expression. e.g. 2 groups of 5
D13: PINE_G2_C06_P1.1.2 | E13: Ch 6 Practice 1.1.2: Describing equal groups | F13: To use mathematical language such as ‘4 threes’ to describe equal groups | G13: M1NS-IIIa-37 | H13: Numbers and Number sense | I13: counts groups of equal quantity using concrete objects up to 50 and writes an equivalent expression. e.g. 2 groups of 5
C14: 1.2 Telling number stories | D14: PINE_G2_C06_P1.2.1 | E14: Ch 6 Practice 1.2.1: Telling number stories | F14: To tell a number story by finding the total number in the groups using repeated addition | G14: M1NS-IIIa-37 | H14: Numbers and Number sense | I14: counts groups of equal quantity using concrete objects up to 50 and writes an equivalent expression. e.g. 2 groups of 5
D15: PINE_G2_C06_P1.2.2 | E15: Ch 6 Practice 1.2.2: Describing equal groups | F15: To use mathematical language such as ‘2 groups of 5’ to describe equal groups | G15: M1NS-IIIa-37 | H15: Numbers and Number sense | I15: counts groups of equal quantity using concrete objects up to 50 and writes an equivalent expression. e.g. 2 groups of 5
B16: Unit 2: Making Multiplication Stories | C16: 2.1 Making multiplication stories | D16: PINE_G2_C06_P2.1.1 | E16: Ch 6 Practice 2.1.1: Illustrating the meaning of multiplication | F16: To use manipulatives to illustrate the meaning of multiplication | G16: M1NS-IIIa-37 | H16: Numbers and Number sense | I16: counts groups of equal quantity using concrete objects up to 50 and writes an equivalent expression. e.g. 2 groups of 5
D17: PINE_G2_C06_P2.1.2 | E17: Ch 6 Practice 2.1.2: Making multiplication stories | F17: To make a number story for a given multiplication sentence | G17: M1NS-IIIa-37 | H17: Numbers and Number sense | I17: counts groups of equal quantity using concrete objects up to 50 and writes an equivalent expression. e.g. 2 groups of 5
D18: PINE_G2_C06_P2.1.3 | E18: Ch 6 Practice 2.1.3: Writing multiplication sentences | F18: To write a number sentence for a given situation involving multiplication | G18: M1NS-IIIa-37 | H18: Numbers and Number sense | I18: counts groups of equal quantity using concrete objects up to 50 and writes an equivalent expression. e.g. 2 groups of 5
D19: PINE_G2_C06_P2.1.4 | E19: Ch 6 Practice 2.1.4: Using array to show multiplication sentences | F19: To understand multiplication as describing an array | G19: M1NS-IIIa-37 | H19: Numbers and Number sense | I19: counts groups of equal quantity using concrete objects up to 50 and writes an equivalent expression. e.g. 2 groups of 5
D20: PINE_G2_C06_P2.1.5 | E20: Ch 6 Practice 2.1.5: Understanding the meaning of product | G20: M1NS-IIIa-37 | H20: Numbers and Number sense | I20: counts groups of equal quantity using concrete objects up to 50 and writes an equivalent expression. e.g. 2 groups of 5
A21: Division | B21: Unit 1: Sharing and Grouping | C21: 1.1 Finding the number of objects in each group | D21: PINE_G2_C07_P1.1.1 | E21: Ch 7 Practice 1.1.1: Finding the number of objects in each group | F21: To use objects and manipulatives to illustrate the sharing concept of division | G21: M1NS-IIIa-48 | H21: Numbers and Number sense | I21: visualizes, represents, and separates objects into groups of equal quantity using concrete objects up to 50. e.g. 10 grouped by 5s
D22: PINE_G2_C07_P1.1.2 | E22: Ch 7 Practice 1.1.2: Understanding that division can leave some left over | F22: To understand that division can leave some left over | G22: M1NS-IIIa-48 | H22: Numbers and Number sense | I22: visualizes, represents, and separates objects into groups of equal quantity using concrete objects up to 50. e.g. 10 grouped by 5s
C23: 1.2 Finding the number of equal groups | D23: PINE_G2_C07_P1.2.1 | E23: Ch 7 Practice 1.2.1: Finding the number of equal groups | F23: To use objects and manipulatives to illustrate the grouping concept of division To find the number of equal groups using a number line | G23: M1NS-IIIa-48 | H23: Numbers and Number sense | I23: visualizes, represents, and separates objects into groups of equal quantity using concrete objects up to 50. e.g. 10 grouped by 5s
D24: PINE_G2_C07_P1.2.2 | E24: Ch 7 Practice 1.2.2: Understanding that division can leave some left over | F24: To understand that division can leave some left over | G24: M1NS-IIIa-48 | H24: Numbers and Number sense | I24: visualizes, represents, and separates objects into groups of equal quantity using concrete objects up to 50. e.g. 10 grouped by 5s
C25: 1.3 Telling division stories | D25: PINE_G2_C07_P1.3.1 | E25: Ch 7 Practice 1.3.1: Telling division stories | F25: To make number stories for a given division sentence | G25: M1NS-IIIa-48 | H25: Numbers and Number sense | I25: visualizes, represents, and separates objects into groups of equal quantity using concrete objects up to 50. e.g. 10 grouped by 5s
A27: GRADE 2
A28: Graphs | B28: Unit 2: Block Graphs | C28: 2.1 Making, reading and interpreting block graphs | D28: PINE_G2_C15_P2.1.1 | E28: Ch 15 Practice 2.1.1: Making block graphs | F28: To present data given in lists and tables as block graphs
D29: PINE_G2_C15_P2.1.2 | E29: Ch 15 Practice 2.1.2: Reading and interpreting block graphs | F29: To read and interpret block graphs
B30: Unit 2A: Line Plots | C30: 2A.1 Making, reading and interpreting line plots | D30: PINE_G2_C15_P2A.1.1 | E30: Ch 15 Practice 2A.1.1: Making, reading and interpreting line plots | F30: To make, read and interpret a line plot
B31: Unit 3: Carroll Diagrams | C31: 3.1 Sorting data in Carroll diagrams | D31: PINE_G2_C15_P3.1.1 | E31: Ch 15 Practice 3.1.1: Grouping objects in Carroll diagrams | F31: To group objects in Carroll diagrams using different criteria
D32: PINE_G2_C15_P3.1.2 | E32: Ch 15 Practice 3.1.2: Sorting data in Carroll diagrams | F32: To sort data in Carroll diagrams with 1 criterion and read the Caroll diagrams
A33: Symmetry | B33: Unit 4: Symmetry | C33: 3.1 Identifying and making symmetric figures | D33: PINE_G2_C16_P3.1.1 | E33: Ch 16 Practice 3.1.1: Identifying symmetric figures | F33: To identify a symmetric figure | G33: M2GE-IIIh-7.1 | H33: Geometry | I33: identifies shapes/figures that show symmetry in a line
D34: PINE_G2_C16_P3.1.2 | E34: Ch 16 Practice 3.1.2: Making symmetric figures | F34: To cut out a symmetric figure from a piece of folded paper | G34: M2GE-IIIh-7.2 | H34: Geometry | I34: creates figures that show symmetry in a line.
D35: PINE_G2_C16_P3.1.3 | E35: Ch 16 Practice 3.1.3: Identifying symmetry in the environment | F35: To find examples of symmetry in the environment | G35: M2GE-IIIh-7.4a | H35: Geometry | I35: identifies and draws the line of symmetry in a given symmetrical figure
C36: 3.2 Identifying and drawing lines of symmetry | D36: PINE_G2_C16_P3.2.1 | E36: Ch 16 Practice 3.2.1: Identifying and drawing lines of symmetry | F36: To determine whether a straight line is a line of symmetry of a figure or pattern To draw a line of symmetry in figures and patterns | G36: M2GE-IIIh-7.4a | H36: Geometry | I36: identifies and draws the line of symmetry in a given symmetrical figure
A37: Capacity | B37: Unit 1: Capacity in Liters | C37: 1.1 Measuring and comparing capacities in liters | D37: PINE_G2_C05_P1.1.1 | E37: Ch 5 Practice 1.1.1: Measuring and comparing capacities in liters | F37: To understand the need for standardized units of measurement of capacity To estimate and measure capacity in liters To compare capacities of two or more containers in liters | G37: M2ME-IVf-33 | H37: Measurement | I37: measures objects using appropriate measuring tools in mL or L
D38: PINE_G2_C05_P1.1.2 | E38: Ch 5 Practice 1.1.2: Ordering capacities in liters | G38: M2ME-IVf-33 | H38: Measurement | I38: measures objects using appropriate measuring tools in mL or L
B39: Unit 2: Problem Solving | C39: 2.1 Word problems | D39: PINE_G2_C05_P2.1.1 | E39: Ch 5 Practice 2.1.1: Word problems | F39: To solve 1-step word problems involving capacity
C40: 2.2 More word problems | D40: PINE_G2_C05_P2.2.1 | E40: Ch 5 Practice 2.2.1: More word problems | F40: To solve 2-step word problems involving capacity
A41: Customary Units of Length | B41: Unit 1: Length in Inches | C41: 1.1 Measuring and comparing lengths in inches | F41: To estimate and measure length in inches To measure the lengths of two objects to determine how much longer one object is than another, expressing the length difference in terms of inches
C42: 1.2 Measuring lines and curves | D42: PINE_G2_C10A_P1.2.1 | E42: Ch 10A Practice 1.2.1: Measuring lines and curves | F42: To measure the length of a line or curve in inches
...

Sheet Grade 1
A1: Chapter (1A: 1-10 1B: 11 - 23) | B1: Unit | C1: Lesson | D1: Digital Practices and Assessments (DPA) | G1: Assessments | J1: PH Tags at item level | P1: Reference ID | Q1: Activity Title | R1: PH Tags at activity level | AK1: MS ready for review | AL1: Cleared by Evonne | AM1: Status update | AP1: Status Update | AQ1: Next course of action | AR1: Comments
D2: Activity Reference (revised) | E2: Activity Title (revised) | F2: Objective | G2: Chpt Assessment | H2: Review | I2: Mid-Year / EOY | J2: PR1ME PH Curriculum Learning Objective Summary | K2: PH Curriculum Learning Objective (Name and Long Name) | N2: PH Curriculum Learning Objective Summary | O2: Question Category | R2: Curriculum | S2: PINE Activity Type | T2: Product Code | U2: PR1ME PH Grade | V2: PR1ME PH Chapter | W2: PR1ME PH ISBN | X2: PR1ME PH Page Number | Y2: PR1ME PH Curriculum Strand | Z2: PR1ME PH Curriculum Substrand | AA2: PR1ME PH National Curriculum Unit | AB2: PR1ME PH Curriculum Learning Objective Summary | AC2: PH Curriculum Strand | AD2: PH Curriculum Substrand | AE2: PH Curriculum Learning Objective (Name and Long Name) | AG2: PH Curriculum Learning Objective Summary | AH2: Chapter Number | AI2: PH Pre-requisite
A3: Chapter 1: Numbers 0 to 10 | B3: Unit 1: Counting and Comparing | C3: 1.1 Counting, reading and writing numbers | D3: PINE_G1_C01_P1.1.1 | E3: Ch 1 Practice 1.1.1: Counting | F3: To count within 10 (including the use of zero to denote an empty set) | G3: 1 | I3: A_01 | J3: 1.001 To count within 10 M1NS-Ia-1.1 | K3: M1NS-Ia-1.1 | L3: Visualizes and represents numbers from 0 to 100 using a variety of materials | M3: M1NS-Ia-1.1: Visualizes and represents numbers from 0 - 100 using a variety of materials. | N3: 1.001 Visualizes and represents numbers from 0 - 100 M1NS-Ia-1.1 | O3: P1/P2/A1/A2 | P3: PH_G1_C01_P1.1.1 | Q3: =E3 -> Ch 1 Practice 1.1.1: Counting | R3: PH, PR1MEPH | S3: Practice | T3: MATHPRO | U3: Grade 1 | V3: Chapter 1 Numbers 0 to 10 | W3: 9789814969369 | X3: 5 | Y3: 1. Numbers and Number Sense | Z3: G1.1.01 Whole Numbers / Place Value | AA3: Counting and Comparing | AB3: =J3 -> 1.001 To count within 10 M1NS-Ia-1.1 | AC3: =Y3 -> 1. Numbers and Number Sense | AD3: =Z3 -> G1.1.01 Whole Numbers / Place Value | AE3: =K3 -> M1NS-Ia-1.1 | AF3: =M3 -> M1NS-Ia-1.1: Visualizes and represents numbers from 0 - 100 using a variety of materials. | AG3: =N3 -> 1.001 Visualizes and represents numbers from 0 - 100 M1NS-Ia-1.1 | AH3: 1 | AI3: n.a. | AJ3: n.a. | AP3: Published | AQ3: =IF($AP3="Raw Manuscript created","Editor to review",IF($AP3="Manuscript reviewed by Editor","Author to revise",IF($AP3="Manuscript revised by Author","Editor to review",IF($AP3="Manuscript finalised by Editor","Evonne to PFP",IF($AP3="Manuscript approved by Evonne","Evelyn to upload to Learnosity",IF($AP3="Manuscript uploaded to Learnosity","Prepress to create Activity",IF($AP3="Ready practice on Learnosity","Prepress to create Activity",IF($AP3="Activity created","Editor to conduct Learnosity review",IF($AP3="Published","Completed",""))))))))) -> Completed
D4: PINE_G1_C01_P1.1.2 | E4: Ch 1 Practice 1.1.2: Reading and writing numbers | F4: To read and write a number from 0 to 10 — the numeral and the corresponding number word | G4: 2 | H4: 1 (Rev1) | I4: B_01 | J4: 1.002 To read and write a number from 0 to 10 — the numeral and the corresponding number word M1NS-Ia-1.1 | K4: M1NS-Ia-1.1 | L4: Visualizes and represents numbers from 0 to 100 using a variety of materials | M4: M1NS-Ia-1.1: Visualizes and represents numbers from 0 - 100 using a variety of materials. | N4: 1.001 Visualizes and represents numbers from 0 - 100 M1NS-Ia-1.1 | O4: P1/P2/A1/A2 | P4: PH_G1_C01_P1.1.2 | Q4: =E4 -> Ch 1 Practice 1.1.2: Reading and writing numbers | R4: PH, PR1MEPH | S4: Practice | T4: MATHPRO | U4: Grade 1 | V4: Chapter 1 Numbers 0 to 10 | W4: 9789814969369 | X4: 5 | Y4: 1. Numbers and Number Sense | Z4: G1.1.01 Whole Numbers / Place Value | AA4: Counting and Comparing | AB4: =J4 -> 1.002 To read and write a number from 0 to 10 — the numeral and the corresponding number word M1NS-Ia-1.1 | AC4: =Y4 -> 1. Numbers and Number Sense | AD4: =Z4 -> G1.1.01 Whole Numbers / Place Value | AE4: =K4 -> M1NS-Ia-1.1 | AF4: =M4 -> M1NS-Ia-1.1: Visualizes and represents numbers from 0 - 100 using a variety of materials. | AG4: =N4 -> 1.001 Visualizes and represents numbers from 0 - 100 M1NS-Ia-1.1 | AH4: 1 | AI4: PH_G1_C01_P1.1.1 | AJ4: To count within 10 (including the use of zero to denote an empty set) | AP4: Published | AQ4: =IF($AP4="Raw Manuscript created","Editor to review",IF($AP4="Manuscript reviewed by Editor","Author to revise",IF($AP4="Manuscript revised by Author","Editor to review",IF($AP4="Manuscript finalised by Editor","Evonne to PFP",IF($AP4="Manuscript approved by Evonne","Evelyn to upload to Learnosity",IF($AP4="Manuscript uploaded to Learnosity","Prepress to create Activity",IF($AP4="Ready practice on Learnosity","Prepress to create Activity",IF($AP4="Activity created","Editor to conduct Learnosity review",IF($AP4="Published","Completed",""))))))))) -> Completed
D5: PINE_G1_C01_P1.1.3 | E5: Ch 1 Practice 1.1.3: Recognizing conservation of numbers | F5: To recognise conservation of number | G5: 3 | J5: 1.003 To recognise conservation of number M1NS-Ia-1.1 | K5: M1NS-Ia-1.1 | L5: Visualizes and represents numbers from 0 to 100 using a variety of materials | M5: M1NS-Ia-1.1: Visualizes and represents numbers from 0 - 100 using a variety of materials. | N5: 1.001 Visualizes and represents numbers from 0 - 100 M1NS-Ia-1.1 | O5: P1/P2/A1/A2 | P5: PH_G1_C01_P1.1.3 | Q5: =E5 -> Ch 1 Practice 1.1.3: Recognizing conservation of numbers | R5: PH, PR1MEPH | S5: Practice | T5: MATHPRO | U5: Grade 1 | V5: Chapter 1 Numbers 0 to 10 | W5: 9789814969369 | X5: 5 | Y5: 1. Numbers and Number Sense | Z5: G1.1.01 Whole Numbers / Place Value | AA5: Counting and Comparing | AB5: =J5 -> 1.003 To recognise conservation of number M1NS-Ia-1.1 | AC5: =Y5 -> 1. Numbers and Number Sense | AD5: =Z5 -> G1.1.01 Whole Numbers / Place Value | AE5: =K5 -> M1NS-Ia-1.1 | AF5: =M5 -> M1NS-Ia-1.1: Visualizes and represents numbers from 0 - 100 using a variety of materials. | AG5: =N5 -> 1.001 Visualizes and represents numbers from 0 - 100 M1NS-Ia-1.1 | AH5: 1 | AI5: PH_G1_C01_P1.1.1 | AJ5: To count within 10 (including the use of zero to denote an empty set) | AP5: Published | AQ5: =IF($AP5="Raw Manuscript created","Editor to review",IF($AP5="Manuscript reviewed by Editor","Author to revise",IF($AP5="Manuscript revised by Author","Editor to review",IF($AP5="Manuscript finalised by Editor","Evonne to PFP",IF($AP5="Manuscript approved by Evonne","Evelyn to upload to Learnosity",IF($AP5="Manuscript uploaded to Learnosity","Prepress to create Activity",IF($AP5="Ready practice on Learnosity","Prepress to create Activity",IF($AP5="Activity created","Editor to conduct Learnosity review",IF($AP5="Published","Completed",""))))))))) -> Completed | AR5: remove row as objective is not in SOW
C6: 1.2 Comparing numbers of objects by matching | D6: PINE_G1_C01_P1.3.1 | E6: Ch 1 Practice 1.2.1: Comparing number of objects by matching | F6: To compare number of objects in two groups within 10 | G6: 4 | H6: 1 (Rev3) | J6: 1.004 To compare number of objects in two groups within 10 M1NS-Id-6 | K6: M1NS-Id-6 | L6: Visualizes, represents, and compares two sets using the expressions “less than,” “more than,” and “as many as” | M6: M1NS-Id-6: Visualizes, represents, and compares two sets using the expressions “less than”, “more than”, and “as many as”. | N6: 1.006 Visualizes, represents, and compares two sets M1NS-Id-6 | O6: P1/P2/A1/A2 | P6: PH_G1_C01_P1.2.1 | Q6: =E6 -> Ch 1 Practice 1.2.1: Comparing number of objects by matching | R6: PH, PR1MEPH | S6: Practice | T6: MATHPRO | U6: Grade 1 | V6: Chapter 1 Numbers 0 to 10 | W6: 9789814969369 | X6: 11 | Y6: 1. Numbers and Number Sense | Z6: G1.1.01 Whole Numbers / Place Value | AA6: Counting and Comparing | AB6: =J6 -> 1.004 To compare number of objects in two groups within 10 M1NS-Id-6 | AC6: =Y6 -> 1. Numbers and Number Sense | AD6: =Z6 -> G1.1.01 Whole Numbers / Place Value | AE6: =K6 -> M1NS-Id-6 | AF6: =M6 -> M1NS-Id-6: Visualizes, represents, and compares two sets using the expressions “less than”, “more than”, and “as many as”. | AG6: =N6 -> 1.006 Visualizes, represents, and compares two sets M1NS-Id-6 | AH6: 1 | AI6: PH_G1_C01_P1.1.1 | AJ6: To count within 10 (including the use of zero to denote an empty set) | AP6: Published | AQ6: =IF($AP6="Raw Manuscript created","Editor to review",IF($AP6="Manuscript reviewed by Editor","Author to revise",IF($AP6="Manuscript revised by Author","Editor to review",IF($AP6="Manuscript finalised by Editor","Evonne to PFP",IF($AP6="Manuscript approved by Evonne","Evelyn to upload to Learnosity",IF($AP6="Manuscript uploaded to Learnosity","Prepress to create Activity",IF($AP6="Ready practice on Learnosity","Prepress to create Activity",IF($AP6="Activity created","Editor to conduct Learnosity review",IF($AP6="Published","Completed",""))))))))) -> Completed
C7: 1.3 Comparing numbers | D7: PINE_G1_C01_P1.4.1 | E7: Ch 1 Practice 1.3.1: Comparing number of objects by counting | F7: To compare number of objects in two groups within 10 | G7: 5 | H7: 2 (Rev1) | J7: 1.005 To compare number of objects in two groups within 10 M1NS-Id-6 | K7: M1NS-Id-6 | L7: Visualizes, represents, and compares two sets using the expressions “less than,” “more than,” and “as many as” | M7: M1NS-Id-6: Visualizes, represents, and compares two sets using the expressions “less than”, “more than”, and “as many as”. | N7: 1.006 Visualizes, represents, and compares two sets M1NS-Id-6 | O7: P1/P2/A1/A2 | P7: PH_G1_C01_P1.3.1 | Q7: =E7 -> Ch 1 Practice 1.3.1: Comparing number of objects by counting | R7: PH, PR1MEPH | S7: Practice | T7: MATHPRO | U7: Grade 1 | V7: Chapter 1 Numbers 0 to 10 | W7: 9789814969369 | X7: 11 | Y7: 1. Numbers and Number Sense | Z7: G1.1.01 Whole Numbers / Place Value | AA7: Counting and Comparing | AB7: =J7 -> 1.005 To compare number of objects in two groups within 10 M1NS-Id-6 | AC7: =Y7 -> 1. Numbers and Number Sense | AD7: =Z7 -> G1.1.01 Whole Numbers / Place Value | AE7: =K7 -> M1NS-Id-6 | AF7: =M7 -> M1NS-Id-6: Visualizes, represents, and compares two sets using the expressions “less than”, “more than”, and “as many as”. | AG7: =N7 -> 1.006 Visualizes, represents, and compares two sets M1NS-Id-6 | AH7: 1 | AI7: PH_G1_C01_P1.1.1 | AJ7: To count within 10 (including the use of zero to denote an empty set) | AP7: Published | AQ7: =IF($AP7="Raw Manuscript created","Editor to review",IF($AP7="Manuscript reviewed by Editor","Author to revise",IF($AP7="Manuscript revised by Author","Editor to review",IF($AP7="Manuscript finalised by Editor","Evonne to PFP",IF($AP7="Manuscript approved by Evonne","Evelyn to upload to Learnosity",IF($AP7="Manuscript uploaded to Learnosity","Prepress to create Activity",IF($AP7="Ready practice on Learnosity","Prepress to create Activity",IF($AP7="Activity created","Editor to conduct Learnosity review",IF($AP7="Published","Completed",""))))))))) -> Completed
D8: PINE_G1_C01_P1.4.2 | E8: Ch 1 Practice 1.3.2: Comparing two numbers | F8: To compare two numbers within 10 | G8: 6 | J8: 1.006 To compare two numbers within 10 M1NS-Id-6 | K8: M1NS-Id-6 | L8: Visualizes, represents, and compares two sets using the expressions “less than,” “more than,” and “as many as” | M8: M1NS-Id-6: Visualizes, represents, and compares two sets using the expressions “less than”, “more than”, and “as many as”. | N8: 1.006 Visualizes, represents, and compares two sets M1NS-Id-6 | O8: P1/P2/A1/A2 | P8: PH_G1_C01_P1.3.2 | Q8: =E8 -> Ch 1 Practice 1.3.2: Comparing two numbers | R8: PH, PR1MEPH | S8: Practice | T8: MATHPRO | U8: Grade 1 | V8: Chapter 1 Numbers 0 to 10 | W8: 9789814969369 | X8: 11 | Y8: 1. Numbers and Number Sense | Z8: G1.1.01 Whole Numbers / Place Value | AA8: Counting and Comparing | AB8: =J8 -> 1.006 To compare two numbers within 10 M1NS-Id-6 | AC8: =Y8 -> 1. Numbers and Number Sense | AD8: =Z8 -> G1.1.01 Whole Numbers / Place Value | AE8: =K8 -> M1NS-Id-6 | AF8: =M8 -> M1NS-Id-6: Visualizes, represents, and compares two sets using the expressions “less than”, “more than”, and “as many as”. | AG8: =N8 -> 1.006 Visualizes, represents, and compares two sets M1NS-Id-6 | AH8: 1 | AI8: PH_G1_C01_P1.3.1 | AJ8: To compare number of objects in two groups within 10 | AP8: Published | AQ8: =IF($AP8="Raw Manuscript created","Editor to review",IF($AP8="Manuscript reviewed by Editor","Author to revise",IF($AP8="Manuscript revised by Author","Editor to review",IF($AP8="Manuscript finalised by Editor","Evonne to PFP",IF($AP8="Manuscript approved by Evonne","Evelyn to upload to Learnosity",IF($AP8="Manuscript uploaded to Learnosity","Prepress to create Activity",IF($AP8="Ready practice on Learnosity","Prepress to create Activity",IF($AP8="Activity created","Editor to conduct Learnosity review",IF($AP8="Published","Completed",""))))))))) -> Completed | AR8: remove row as objective is not in SOW
D9: PINE_G1_C01_P1.4.3 | E9: Ch 1 Practice 1.3.3: Using the = sign | F9: To use the = sign to represent equality | G9: 7 | I9: EOY_1 | J9: 1.007 To use the = sign to represent equality M1NS-Ih-12.1 | K9: M1NS-Ih-12.1 | L9: Visualizes, represents, and compares numbers up to 100 using relation symbols | M9: M1NS-Ih-12.1: Visualizes, represents, and compares numbers up to 100 using relation symbols. | N9: 1.012 Visualizes, represents, and compares numbers up to 100 M1NS-Ih-12.1 | O9: P1/P2/A1/A2 | P9: PH_G1_C01_P1.3.3 | Q9: =E9 -> Ch 1 Practice 1.3.3: Using the = sign | R9: PH, PR1MEPH | S9: Practice | T9: MATHPRO | U9: Grade 1 | V9: Chapter 1 Numbers 0 to 10 | W9: 9789814969369 | X9: 11 | Y9: 1. Numbers and Number Sense | Z9: G1.1.01 Whole Numbers / Place Value | AA9: Counting and Comparing | AB9: =J9 -> 1.007 To use the = sign to represent equality M1NS-Ih-12.1 | AC9: =Y9 -> 1. Numbers and Number Sense | AD9: =Z9 -> G1.1.01 Whole Numbers / Place Value | AE9: =K9 -> M1NS-Ih-12.1 | AF9: =M9 -> M1NS-Ih-12.1: Visualizes, represents, and compares numbers up to 100 using relation symbols. | AG9: =N9 -> 1.012 Visualizes, represents, and compares numbers up to 100 M1NS-Ih-12.1 | AH9: 1 | AI9: PH_G1_C01_P1.3.2 | AJ9: To compare two numbers within 10 | AP9: Published | AQ9: =IF($AP9="Raw Manuscript created","Editor to review",IF($AP9="Manuscript reviewed by Editor","Author to revise",IF($AP9="Manuscript revised by Author","Editor to review",IF($AP9="Manuscript finalised by Editor","Evonne to PFP",IF($AP9="Manuscript approved by Evonne","Evelyn to upload to Learnosity",IF($AP9="Manuscript uploaded to Learnosity","Prepress to create Activity",IF($AP9="Ready practice on Learnosity","Prepress to create Activity",IF($AP9="Activity created","Editor to conduct Learnosity review",IF($AP9="Published","Completed",""))))))))) -> Completed | AR9: remove row as objective is not in SOW
C10: 1.4 Counting on and backwards | D10: PINE_G1_C01_P1.2.1 | E10: Ch 1 Practice 1.4.1: Counting on and backwards | F10: To count on and backwards within 10 | G10: 8 | H10: 3 (Rev1) | J10: 1.008 To count on and backwards within 10 M1NS-Ib-2.1 | K10: M1NS-Ib-2.1 | L10: Counts the number of objects in a given set by ones and tens | M10: M1NS-Ib-2.1: Counts the number of objects in a given set by ones and tens. | N10: 1.002 Counts the number of objects in a given set by ones and tens M1NS-Ib-2.1 | O10: P1/P2/A1/A2 | P10: PH_G1_C01_P1.4.1 | Q10: =E10 -> Ch 1 Practice 1.4.1: Counting on and backwards | R10: PH, PR1MEPH | S10: Practice | T10: MATHPRO | U10: Grade 1 | V10: Chapter 1 Numbers 0 to 10 | W10: 9789814969369 | X10: 13 | Y10: 1. Numbers and Number Sense | Z10: G1.1.01 Whole Numbers / Place Value | AA10: Counting and Comparing | AB10: =J10 -> 1.008 To count on and backwards within 10 M1NS-Ib-2.1 | AC10: =Y10 -> 1. Numbers and Number Sense | AD10: =Z10 -> G1.1.01 Whole Numbers / Place Value | AE10: =K10 -> M1NS-Ib-2.1 | AF10: =M10 -> M1NS-Ib-2.1: Counts the number of objects in a given set by ones and tens. | AG10: =N10 -> 1.002 Counts the number of objects in a given set by ones and tens M1NS-Ib-2.1 | AH10: 1 | AI10: PH_G1_C01_P1.1.1 | AJ10: To count within 10 (including the use of zero to denote an empty set) | AP10: Published | AQ10: =IF($AP10="Raw Manuscript created","Editor to review",IF($AP10="Manuscript reviewed by Editor","Author to revise",IF($AP10="Manuscript revised by Author","Editor to review",IF($AP10="Manuscript finalised by Editor","Evonne to PFP",IF($AP10="Manuscript approved by Evonne","Evelyn to upload to Learnosity",IF($AP10="Manuscript uploaded to Learnosity","Prepress to create Activity",IF($AP10="Ready practice on Learnosity","Prepress to create Activity",IF($AP10="Activity created","Editor to conduct Learnosity review",IF($AP10="Published","Completed",""))))))))) -> Completed
D11: PINE_G1_C01_P1.5.1 | E11: Ch 1 Practice 1.4.2: Comparing and ordering numbers | F11: To compare and order numbers within 10 | G11: 9 | I11: B_06 | J11: 1.009 To compare and order numbers within 10 M1NS-Ie-7 | K11: M1NS-Ie-7 | L11: Visualizes, represents, and orders sets from least to greatest and vice versa | M11: M1NS-Ie-7: Visualizes, represents, and orders sets from least to greatest and vice versa. | N11: 1.007 Visualizes, represents, and orders sets from least to greatest and vice versa M1NS-Ie-7 | O11: P1/P2/A1/A2 | P11: PH_G1_C01_P1.4.2 | Q11: =E11 -> Ch 1 Practice 1.4.2: Comparing and ordering numbers | R11: PH, PR1MEPH | S11: Practice | T11: MATHPRO | U11: Grade 1 | V11: Chapter 1 Numbers 0 to 10 | W11: 9789814969369 | X11: 13 | Y11: 1. Numbers and Number Sense | Z11: G1.1.01 Whole Numbers / Place Value | AA11: Counting and Comparing | AB11: =J11 -> 1.009 To compare and order numbers within 10 M1NS-Ie-7 | AC11: =Y11 -> 1. Numbers and Number Sense | AD11: =Z11 -> G1.1.01 Whole Numbers / Place Value | AE11: =K11 -> M1NS-Ie-7 | AF11: =M11 -> M1NS-Ie-7: Visualizes, represents, and orders sets from least to greatest and vice versa. | AG11: =N11 -> 1.007 Visualizes, represents, and orders sets from least to greatest and vice versa M1NS-Ie-7 | AH11: 1 | AI11: PH_G1_C01_P1.4.1 | AJ11: To count on and backwards within 10 | AP11: Published | AQ11: =IF($AP11="Raw Manuscript created","Editor to review",IF($AP11="Manuscript reviewed by Editor","Author to revise",IF($AP11="Manuscript revised by Author","Editor to review",IF($AP11="Manuscript finalised by Editor","Evonne to PFP",IF($AP11="Manuscript approved by Evonne","Evelyn to upload to Learnosity",IF($AP11="Manuscript uploaded to Learnosity","Prepress to create Activity",IF($AP11="Ready practice on Learnosity","Prepress to create Activity",IF($AP11="Activity created","Editor to conduct Learnosity review",IF($AP11="Published","Completed",""))))))))) -> Completed | AR11: remove row as objective is not in SOW
A12: Chapter 2: Number Bonds | B12: Unit 1: Telling Number Stories | C12: 1.1 Making 5 | D12: PINE_G1_C02_P1.1.1 | E12: Ch 2 Practice 1.1.1: Making a number story for 5 | F12: To make a number story to illustrate a number bond for 5 | G12: 1 | J12: 1.010 To make a number story to illustrate a number bond for 5 M1AL-IIIi-9 | K12: M1AL-IIIi-9 | L12: Identifies and creates patterns to compose and decompose using addition eg 7 = 0 + 7, 1 + 6, 2 + 5, 3 + 4, 4 + 3, 5 + 2, 6 + 1, 7 + 0 | M12: M1AL-IIIi-9: Identifies and creates patterns to compose and decompose using addition. | N12: 1.051 Identifies and creates patterns to compose and decompose M1AL-IIIi-9 | O12: P1/P2/A1/A2 | P12: PH_G1_C02_P1.1.1 | Q12: =E12 -> Ch 2 Practice 1.1.1: Making a number story for 5 | R12: PH, PR1MEPH | S12: Practice | T12: MATHPRO | U12: Grade 1 | V12: Chapter 2 Number Bonds | W12: 9789814969369 | X12: 16 | Y12: 1. Numbers and Number Sense | Z12: G1.1.01 Whole Numbers / Place Value | AA12: Telling number stories | AB12: =J12 -> 1.010 To make a number story to illustrate a number bond for 5 M1AL-IIIi-9 | AC12: =Y12 -> 1. Numbers and Number Sense | AD12: =Z12 -> G1.1.01 Whole Numbers / Place Value | AE12: =K12 -> M1AL-IIIi-9 | AF12: =M12 -> M1AL-IIIi-9: Identifies and creates patterns to compose and decompose using addition. | AG12: =N12 -> 1.051 Identifies and creates patterns to compose and decompose M1AL-IIIi-9 | AH12: 2 | AI12: PH_G1_C01_P1.1.1 | AJ12: To count within 10 (including the use of zero to denote an empty set) | AP12: Published | AQ12: =IF($AP12="Raw Manuscript created","Editor to review",IF($AP12="Manuscript reviewed by Editor","Author to revise",IF($AP12="Manuscript revised by Author","Editor to review",IF($AP12="Manuscript finalised by Editor","Evonne to PFP",IF($AP12="Manuscript approved by Evonne","Evelyn to upload to Learnosity",IF($AP12="Manuscript uploaded to Learnosity","Prepress to create Activity",IF($AP12="Ready practice on Learnosity","Prepress to create Activity",IF($AP12="Activity created","Editor to conduct Learnosity review",IF($AP12="Published","Completed",""))))))))) -> Completed
D13: PINE_G1_C02_P1.1.2 | E13: Ch 2 Practice 1.1.2: Making 5 | F13: To break a set of 5 objects into two parts in different ways | G13: 2 | J13: 1.011 To break a set of 5 objects into two parts in different ways M1NS-Ic-4 | K13: M1NS-Ic-4 | L13: Composes and decomposes a given number eg 5 is 5 and 0, 4 and 1, 3 and 2, 2 and 3, 1 and 4, 0 and 5 | M13: M1NS-Ic-4: Composes and decomposes a given number. | N13: 1.004 Composes and decomposes a given number M1NS-Ic-4 | O13: P1/P2/A1/A2 | P13: PH_G1_C02_P1.1.2 | Q13: =E13 -> Ch 2 Practice 1.1.2: Making 5 | R13: PH, PR1MEPH | S13: Practice | T13: MATHPRO | U13: Grade 1 | V13: Chapter 2 Number Bonds | W13: 9789814969369 | X13: 16 | Y13: 1. Numbers and Number Sense | Z13: G1.1.01 Whole Numbers / Place Value | AA13: Telling number stories | AB13: =J13 -> 1.011 To break a set of 5 objects into two parts in different ways M1NS-Ic-4 | AC13: =Y13 -> 1. Numbers and Number Sense | AD13: =Z13 -> G1.1.01 Whole Numbers / Place Value | AE13: =K13 -> M1NS-Ic-4 | AF13: =M13 -> M1NS-Ic-4: Composes and decomposes a given number. | AG13: =N13 -> 1.004 Composes and decomposes a given number M1NS-Ic-4 | AH13: 2 | AI13: PH_G1_C02_P1.1.1 | AJ13: To make a number story to illustrate a number bond for 5 | AP13: Published | AQ13: =IF($AP13="Raw Manuscript created","Editor to review",IF($AP13="Manuscript reviewed by Editor","Author to revise",IF($AP13="Manuscript revised by Author","Editor to review",IF($AP13="Manuscript finalised by Editor","Evonne to PFP",IF($AP13="Manuscript approved by Evonne","Evelyn to upload to Learnosity",IF($AP13="Manuscript uploaded to Learnosity","Prepress to create Activity",IF($AP13="Ready practice on Learnosity","Prepress to create Activity",IF($AP13="Activity created","Editor to conduct Learnosity review",IF($AP13="Published","Completed",""))))))))) -> Completed
D14: PINE_G1_C02_P1.1.3 | E14: Ch 2 Practice 1.1.3: Writing number bonds for 5 | F14: To write a number bond for 5 | G14: 3 | H14: 4 (Rev1) | J14: 1.012 To write a number bond for 5 M1NS-Ic-4 | K14: M1NS-Ic-4 | L14: Composes and decomposes a given number eg 5 is 5 and 0, 4 and 1, 3 and 2, 2 and 3, 1 and 4, 0 and 5 | M14: M1NS-Ic-4: Composes and decomposes a given number. | N14: 1.004 Composes and decomposes a given number M1NS-Ic-4 | O14: P1/P2/A1/A2 | P14: PH_G1_C02_P1.1.3 | Q14: =E14 -> Ch 2 Practice 1.1.3: Writing number bonds for 5 | R14: PH, PR1MEPH | S14: Practice | T14: MATHPRO | U14: Grade 1 | V14: Chapter 2 Number Bonds | W14: 9789814969369 | X14: 16 | Y14: 1. Numbers and Number Sense | Z14: G1.1.01 Whole Numbers / Place Value | AA14: Telling number stories | AB14: =J14 -> 1.012 To write a number bond for 5 M1NS-Ic-4 | AC14: =Y14 -> 1. Numbers and Number Sense | AD14: =Z14 -> G1.1.01 Whole Numbers / Place Value | AE14: =K14 -> M1NS-Ic-4 | AF14: =M14 -> M1NS-Ic-4: Composes and decomposes a given number. | AG14: =N14 -> 1.004 Composes and decomposes a given number M1NS-Ic-4 | AH14: 2 | AI14: PH_G1_C02_P1.1.2 | AJ14: To break a set of 5 objects into two parts in different ways | AP14: Published | AQ14: =IF($AP14="Raw Manuscript created","Editor to review",IF($AP14="Manuscript reviewed by Editor","Author to revise",IF($AP14="Manuscript revised by Author","Editor to review",IF($AP14="Manuscript finalised by Editor","Evonne to PFP",IF($AP14="Manuscript approved by Evonne","Evelyn to upload to Learnosity",IF($AP14="Manuscript uploaded to Learnosity","Prepress to create Activity",IF($AP14="Ready practice on Learnosity","Prepress to create Activity",IF($AP14="Activity created","Editor to conduct Learnosity review",IF($AP14="Published","Completed",""))))))))) -> Completed
C15: 1.2 Making 6 | D15: PINE_G1_C02_P1.2.1 | E15: Ch 2 Practice 1.2.1: Making a number story for 6 | F15: To make a number story to illustrate a number bond for 6 | G15: 4 | J15: 1.013 To make a number story to illustrate a number bond for 6 M1AL-IIIi-9 | K15: M1AL-IIIi-9 | L15: Identifies and creates patterns to compose and decompose using addition eg 7 = 0 + 7, 1 + 6, 2 + 5, 3 + 4, 4 + 3, 5 + 2, 6 + 1, 7 + 0 | M15: M1AL-IIIi-9: Identifies and creates patterns to compose and decompose using addition. | N15: 1.051 Identifies and creates patterns to compose and decompose M1AL-IIIi-9 | O15: P1/P2/A1/A2 | P15: PH_G1_C02_P1.2.1 | Q15: =E15 -> Ch 2 Practice 1.2.1: Making a number story for 6 | R15: PH, PR1MEPH | S15: Practice | T15: MATHPRO | U15: Grade 1 | V15: Chapter 2 Number Bonds | W15: 9789814969369 | X15: 16 | Y15: 1. Numbers and Number Sense | Z15: G1.1.01 Whole Numbers / Place Value | AA15: Telling number stories | AB15: =J15 -> 1.013 To make a number story to illustrate a number bond for 6 M1AL-IIIi-9 | AC15: =Y15 -> 1. Numbers and Number Sense | AD15: =Z15 -> G1.1.01 Whole Numbers / Place Value | AE15: =K15 -> M1AL-IIIi-9 | AF15: =M15 -> M1AL-IIIi-9: Identifies and creates patterns to compose and decompose using addition. | AG15: =N15 -> 1.051 Identifies and creates patterns to compose and decompose M1AL-IIIi-9 | AH15: 2 | AI15: PH_G1_C01_P1.1.1 | AJ15: To count within 10 (including the use of zero to denote an empty set) | AP15: Published | AQ15: =IF($AP15="Raw Manuscript created","Editor to review",IF($AP15="Manuscript reviewed by Editor","Author to revise",IF($AP15="Manuscript revised by Author","Editor to review",IF($AP15="Manuscript finalised by Editor","Evonne to PFP",IF($AP15="Manuscript approved by Evonne","Evelyn to upload to Learnosity",IF($AP15="Manuscript uploaded to Learnosity","Prepress to create Activity",IF($AP15="Ready practice on Learnosity","Prepress to create Activity",IF($AP15="Activity created","Editor to conduct Learnosity review",IF($AP15="Published","Completed",""))))))))) -> Completed
D16: PINE_G1_C02_P1.2.2 | E16: Ch 2 Practice 1.2.2: Making 6 | F16: To break a set of 6 objects into two parts in different ways | G16: 5 | J16: 1.014 To break a set of 6 objects into two parts in different ways M1NS-Ic-4 | K16: M1NS-Ic-4 | L16: Composes and decomposes a given number eg 5 is 5 and 0, 4 and 1, 3 and 2, 2 and 3, 1 and 4, 0 and 5 | M16: M1NS-Ic-4: Composes and decomposes a given number. | N16: 1.004 Composes and decomposes a given number M1NS-Ic-4 | O16: P1/P2/A1/A2 | P16: PH_G1_C02_P1.2.2 | Q16: =E16 -> Ch 2 Practice 1.2.2: Making 6 | R16: PH, PR1MEPH | S16: Practice | T16: MATHPRO | U16: Grade 1 | V16: Chapter 2 Number Bonds | W16: 9789814969369 | X16: 16 | Y16: 1. Numbers and Number Sense | Z16: G1.1.01 Whole Numbers / Place Value | AA16: Telling number stories | AB16: =J16 -> 1.014 To break a set of 6 objects into two parts in different ways M1NS-Ic-4 | AC16: =Y16 -> 1. Numbers and Number Sense | AD16: =Z16 -> G1.1.01 Whole Numbers / Place Value | AE16: =K16 -> M1NS-Ic-4 | AF16: =M16 -> M1NS-Ic-4: Composes and decomposes a given number. | AG16: =N16 -> 1.004 Composes and decomposes a given number M1NS-Ic-4 | AH16: 2 | AI16: PH_G1_C02_P1.2.1 | AJ16: To make a number story to illustrate a number bond for 6 | AP16: Published | AQ16: =IF($AP16="Raw Manuscript created","Editor to review",IF($AP16="Manuscript reviewed by Editor","Author to revise",IF($AP16="Manuscript revised by Author","Editor to review",IF($AP16="Manuscript finalised by Editor","Evonne to PFP",IF($AP16="Manuscript approved by Evonne","Evelyn to upload to Learnosity",IF($AP16="Manuscript uploaded to Learnosity","Prepress to create Activity",IF($AP16="Ready practice on Learnosity","Prepress to create Activity",IF($AP16="Activity created","Editor to conduct Learnosity review",IF($AP16="Published","Completed",""))))))))) -> Completed
D17: PINE_G1_C02_P1.2.3 | E17: Ch 2 Practice 1.2.3: Writing number bonds for 6 | F17: To write a number bond for 6 | G17: Objective not tested in CA, to be tested in MYE or EOY | I17: EOY_2 | J17: 1.015 To write a number bond for 6 M1NS-Ic-4 | K17: M1NS-Ic-4 | L17: Composes and decomposes a given number eg 5 is 5 and 0, 4 and 1, 3 and 2, 2 and 3, 1 and 4, 0 and 5 | M17: M1NS-Ic-4: Composes and decomposes a given number. | N17: 1.004 Composes and decomposes a given number M1NS-Ic-4 | O17: P1/P2/A1/A2 | P17: PH_G1_C02_P1.2.3 | Q17: =E17 -> Ch 2 Practice 1.2.3: Writing number bonds for 6 | R17: PH, PR1MEPH | S17: Practice | T17: MATHPRO | U17: Grade 1 | V17: Chapter 2 Number Bonds | W17: 9789814969369 | X17: 16 | Y17: 1. Numbers and Number Sense | Z17: G1.1.01 Whole Numbers / Place Value | AA17: Telling number stories | AB17: =J17 -> 1.015 To write a number bond for 6 M1NS-Ic-4 | AC17: =Y17 -> 1. Numbers and Number Sense | AD17: =Z17 -> G1.1.01 Whole Numbers / Place Value | AE17: =K17 -> M1NS-Ic-4 | AF17: =M17 -> M1NS-Ic-4: Composes and decomposes a given number. | AG17: =N17 -> 1.004 Composes and decomposes a given number M1NS-Ic-4 | AH17: 2 | AI17: PH_G1_C02_P1.2.2 | AJ17: To break a set of 6 objects into two parts in different ways | AP17: Published | AQ17: =IF($AP17="Raw Manuscript created","Editor to review",IF($AP17="Manuscript reviewed by Editor","Author to revise",IF($AP17="Manuscript revised by Author","Editor to review",IF($AP17="Manuscript finalised by Editor","Evonne to PFP",IF($AP17="Manuscript approved by Evonne","Evelyn to upload to Learnosity",IF($AP17="Manuscript uploaded to Learnosity","Prepress to create Activity",IF($AP17="Ready practice on Learnosity","Prepress to create Activity",IF($AP17="Activity created","Editor to conduct Learnosity review",IF($AP17="Published","Completed",""))))))))) -> Completed
C18: 1.3 Making 7 | D18: PINE_G1_C02_P1.3.1 | E18: Ch 2 Practice 1.3.1: Making a number story for 7 | F18: To make a number story to illustrate a number bond for 7 | J18: 1.016 To make a number story to illustrate a number bond for 7 M1AL-IIIi-9 | K18: M1AL-IIIi-9 | L18: Identifies and creates patterns to compose and decompose using addition | M18: M1AL-IIIi-9: Identifies and creates patterns to compose and decompose using addition. | N18: 1.051 Identifies and creates patterns to compose and decompose M1AL-IIIi-9 | O18: P1/P2/A1/A2 | P18: PH_G1_C02_P1.3.1 | Q18: =E18 -> Ch 2 Practice 1.3.1: Making a number story for 7 | R18: PH, PR1MEPH | S18: Practice | T18: MATHPRO | U18: Grade 1 | V18: Chapter 2 Number Bonds | W18: 9789814969369 | X18: 18 | Y18: 1. Numbers and Number Sense | Z18: G1.1.01 Whole Numbers / Place Value | AA18: Telling number stories | AB18: =J18 -> 1.016 To make a number story to illustrate a number bond for 7 M1AL-IIIi-9 | AC18: =Y18 -> 1. Numbers and Number Sense | AD18: =Z18 -> G1.1.01 Whole Numbers / Place Value | AE18: =K18 -> M1AL-IIIi-9 | AF18: =M18 -> M1AL-IIIi-9: Identifies and creates patterns to compose and decompose using addition. | AG18: =N18 -> 1.051 Identifies and creates patterns to compose and decompose M1AL-IIIi-9 | AH18: 2 | AI18: PH_G1_C01_P1.1.1 | AJ18: To count within 10 (including the use of zero to denote an empty set) | AP18: Published | AQ18: =IF($AP18="Raw Manuscript created","Editor to review",IF($AP18="Manuscript reviewed by Editor","Author to revise",IF($AP18="Manuscript revised by Author","Editor to review",IF($AP18="Manuscript finalised by Editor","Evonne to PFP",IF($AP18="Manuscript approved by Evonne","Evelyn to upload to Learnosity",IF($AP18="Manuscript uploaded to Learnosity","Prepress to create Activity",IF($AP18="Ready practice on Learnosity","Prepress to create Activity",IF($AP18="Activity created","Editor to conduct Learnosity review",IF($AP18="Published","Completed",""))))))))) -> Completed
D19: PINE_G1_C02_P1.3.2 | E19: Ch 2 Practice 1.3.2: Making 7 | F19: To break a set of 7 objects into two parts in different ways | G19: 6 | J19: 1.017 To break a set of 7 objects into two parts in different ways M1NS-Ic-4 | K19: M1NS-Ic-4 | L19: Composes and decomposes a given number eg 5 is 5 and 0, 4 and 1, 3 and 2, 2 and 3, 1 and 4, 0 and 5 | M19: M1NS-Ic-4: Composes and decomposes a given number. | N19: 1.004 Composes and decomposes a given number M1NS-Ic-4 | O19: P1/P2/A1/A2 | P19: PH_G1_C02_P1.3.2 | Q19: =E19 -> Ch 2 Practice 1.3.2: Making 7 | R19: PH, PR1MEPH | S19: Practice | T19: MATHPRO | U19: Grade 1 | V19: Chapter 2 Number Bonds | W19: 9789814969369 | X19: 18 | Y19: 1. Numbers and Number Sense | Z19: G1.1.01 Whole Numbers / Place Value | AA19: Telling number stories | AB19: =J19 -> 1.017 To break a set of 7 objects into two parts in different ways M1NS-Ic-4 | AC19: =Y19 -> 1. Numbers and Number Sense | AD19: =Z19 -> G1.1.01 Whole Numbers / Place Value | AE19: =K19 -> M1NS-Ic-4 | AF19: =M19 -> M1NS-Ic-4: Composes and decomposes a given number. | AG19: =N19 -> 1.004 Composes and decomposes a given number M1NS-Ic-4 | AH19: 2 | AI19: PH_G1_C02_P1.3.1 | AJ19: To make a number story to illustrate a number bond for 7 | AP19: Published | AQ19: =IF($AP19="Raw Manuscript created","Editor to review",IF($AP19="Manuscript reviewed by Editor","Author to revise",IF($AP19="Manuscript revised by Author","Editor to review",IF($AP19="Manuscript finalised by Editor","Evonne to PFP",IF($AP19="Manuscript approved by Evonne","Evelyn to upload to Learnosity",IF($AP19="Manuscript uploaded to Learnosity","Prepress to create Activity",IF($AP19="Ready practice on Learnosity","Prepress to create Activity",IF($AP19="Activity created","Editor to conduct Learnosity review",IF($AP19="Published","Completed",""))))))))) -> Completed
D20: PINE_G1_C02_P1.3.3 | E20: Ch 2 Practice 1.3.3: Writing number bonds for 7 | F20: To write a number bond for 7 | G20: 7 | H20: 1 (Rev 4) | J20: 1.018 To write a number bond for 7 M1NS-Ic-4 | K20: M1NS-Ic-4 | L20: Composes and decomposes a given number eg 5 is 5 and 0, 4 and 1, 3 and 2, 2 and 3, 1 and 4, 0 and 5 | M20: M1NS-Ic-4: Composes and decomposes a given number. | N20: 1.004 Composes and decomposes a given number M1NS-Ic-4 | O20: P1/P2/A1/A2 | P20: PH_G1_C02_P1.3.3 | Q20: =E20 -> Ch 2 Practice 1.3.3: Writing number bonds for 7 | R20: PH, PR1MEPH | S20: Practice | T20: MATHPRO | U20: Grade 1 | V20: Chapter 2 Number Bonds | W20: 9789814969369 | X20: 18 | Y20: 1. Numbers and Number Sense | Z20: G1.1.01 Whole Numbers / Place Value | AA20: Telling number stories | AB20: =J20 -> 1.018 To write a number bond for 7 M1NS-Ic-4 | AC20: =Y20 -> 1. Numbers and Number Sense | AD20: =Z20 -> G1.1.01 Whole Numbers / Place Value | AE20: =K20 -> M1NS-Ic-4 | AF20: =M20 -> M1NS-Ic-4: Composes and decomposes a given number. | AG20: =N20 -> 1.004 Composes and decomposes a given number M1NS-Ic-4 | AH20: 2 | AI20: PH_G1_C02_P1.3.2 | AJ20: To break a set of 7 objects into two parts in different ways | AP20: Published | AQ20: =IF($AP20="Raw Manuscript created","Editor to review",IF($AP20="Manuscript reviewed by Editor","Author to revise",IF($AP20="Manuscript revised by Author","Editor to review",IF($AP20="Manuscript finalised by Editor","Evonne to PFP",IF($AP20="Manuscript approved by Evonne","Evelyn to upload to Learnosity",IF($AP20="Manuscript uploaded to Learnosity","Prepress to create Activity",IF($AP20="Ready practice on Learnosity","Prepress to create Activity",IF($AP20="Activity created","Editor to conduct Learnosity review",IF($AP20="Published","Completed",""))))))))) -> Completed
C21: 1.4 Making 8 | D21: PINE_G1_C02_P1.4.1 | E21: Ch 2 Practice 1.4.1: Making a number story for 8 | F21: To make a number story to illustrate a number bond for 8 | G21: 8 | H21: 5 (Rev1) | J21: 1.019 To make a number story to illustrate a number bond for 8 M1AL-IIIi-9 | K21: M1AL-IIIi-9 | L21: Identifies and creates patterns to compose and decompose using addition eg 7 = 0 + 7, 1 + 6, 2 + 5, 3 + 4, 4 + 3, 5 + 2, 6 + 1, 7 + 0 | M21: M1AL-IIIi-9: Identifies and creates patterns to compose and decompose using addition. | N21: 1.051 Identifies and creates patterns to compose and decompose M1AL-IIIi-9 | O21: P1/P2/A1/A2 | P21: PH_G1_C02_P1.4.1 | Q21: =E21 -> Ch 2 Practice 1.4.1: Making a number story for 8 | R21: PH, PR1MEPH | S21: Practice | T21: MATHPRO | U21: Grade 1 | V21: Chapter 2 Number Bonds | W21: 9789814969369 | X21: 19 | Y21: 1. Numbers and Number Sense | Z21: G1.1.01 Whole Numbers / Place Value | AA21: Telling number stories | AB21: =J21 -> 1.019 To make a number story to illustrate a number bond for 8 M1AL-IIIi-9 | AC21: =Y21 -> 1. Numbers and Number Sense | AD21: =Z21 -> G1.1.01 Whole Numbers / Place Value | AE21: =K21 -> M1AL-IIIi-9 | AF21: =M21 -> M1AL-IIIi-9: Identifies and creates patterns to compose and decompose using addition. | AG21: =N21 -> 1.051 Identifies and creates patterns to compose and decompose M1AL-IIIi-9 | AH21: 2 | AI21: PH_G1_C01_P1.1.1 | AJ21: To count within 10 (including the use of zero to denote an empty set) | AP21: Published | AQ21: =IF($AP21="Raw Manuscript created","Editor to review",IF($AP21="Manuscript reviewed by Editor","Author to revise",IF($AP21="Manuscript revised by Author","Editor to review",IF($AP21="Manuscript finalised by Editor","Evonne to PFP",IF($AP21="Manuscript approved by Evonne","Evelyn to upload to Learnosity",IF($AP21="Manuscript uploaded to Learnosity","Prepress to create Activity",IF($AP21="Ready practice on Learnosity","Prepress to create Activity",IF($AP21="Activity created","Editor to conduct Learnosity review",IF($AP21="Published","Completed",""))))))))) -> Completed
D22: PINE_G1_C02_P1.4.2 | E22: Ch 2 Practice 1.4.2: Making 8 | F22: To break a set of 8 objects into two parts in different ways | J22: 1.020 To break a set of 8 objects into two parts in different ways M1NS-Ic-4 | K22: M1NS-Ic-4 | L22: Composes and decomposes a given number eg 5 is 5 and 0, 4 and 1, 3 and 2, 2 and 3, 1 and 4, 0 and 5 | M22: M1NS-Ic-4: Composes and decomposes a given number. | N22: 1.004 Composes and decomposes a given number M1NS-Ic-4 | O22: P1/P2/A1/A2 | P22: PH_G1_C02_P1.4.2 | Q22: =E22 -> Ch 2 Practice 1.4.2: Making 8 | R22: PH, PR1MEPH | S22: Practice | T22: MATHPRO | U22: Grade 1 | V22: Chapter 2 Number Bonds | W22: 9789814969369 | X22: 19 | Y22: 1. Numbers and Number Sense | Z22: G1.1.01 Whole Numbers / Place Value | AA22: Telling number stories | AB22: =J22 -> 1.020 To break a set of 8 objects into two parts in different ways M1NS-Ic-4 | AC22: =Y22 -> 1. Numbers and Number Sense | AD22: =Z22 -> G1.1.01 Whole Numbers / Place Value | AE22: =K22 -> M1NS-Ic-4 | AF22: =M22 -> M1NS-Ic-4: Composes and decomposes a given number. | AG22: =N22 -> 1.004 Composes and decomposes a given number M1NS-Ic-4 | AH22: 2 | AI22: PH_G1_C02_P1.4.1 | AJ22: To make a number story to illustrate a number bond for 8 | AP22: Published | AQ22: =IF($AP22="Raw Manuscript created","Editor to review",IF($AP22="Manuscript reviewed by Editor","Author to revise",IF($AP22="Manuscript revised by Author","Editor to review",IF($AP22="Manuscript finalised by Editor","Evonne to PFP",IF($AP22="Manuscript approved by Evonne","Evelyn to upload to Learnosity",IF($AP22="Manuscript uploaded to Learnosity","Prepress to create Activity",IF($AP22="Ready practice on Learnosity","Prepress to create Activity",IF($AP22="Activity created","Editor to conduct Learnosity review",IF($AP22="Published","Completed",""))))))))) -> Completed
D23: PINE_G1_C02_P1.4.3 | E23: Ch 2 Practice 1.4.3: Writing number bonds for 8 | F23: To write a number bond for 8 | G23: 9 | J23: 1.021 To write a number bond for 8 M1NS-Ic-4 | K23: M1NS-Ic-4 | L23: Composes and decomposes a given number eg 5 is 5 and 0, 4 and 1, 3 and 2, 2 and 3, 1 and 4, 0 and 5 | M23: M1NS-Ic-4: Composes and decomposes a given number. | N23: 1.004 Composes and decomposes a given number M1NS-Ic-4 | O23: P1/P2/A1/A2 | P23: PH_G1_C02_P1.4.3 | Q23: =E23 -> Ch 2 Practice 1.4.3: Writing number bonds for 8 | R23: PH, PR1MEPH | S23: Practice | T23: MATHPRO | U23: Grade 1 | V23: Chapter 2 Number Bonds | W23: 9789814969369 | X23: 19 | Y23: 1. Numbers and Number Sense | Z23: G1.1.01 Whole Numbers / Place Value | AA23: Telling number stories | AB23: =J23 -> 1.021 To write a number bond for 8 M1NS-Ic-4 | AC23: =Y23 -> 1. Numbers and Number Sense | AD23: =Z23 -> G1.1.01 Whole Numbers / Place Value | AE23: =K23 -> M1NS-Ic-4 | AF23: =M23 -> M1NS-Ic-4: Composes and decomposes a given number. | AG23: =N23 -> 1.004 Composes and decomposes a given number M1NS-Ic-4 | AH23: 2 | AI23: PH_G1_C02_P1.4.2 | AJ23: To break a set of 8 objects into two parts in different ways | AP23: Published | AQ23: =IF($AP23="Raw Manuscript created","Editor to review",IF($AP23="Manuscript reviewed by Editor","Author to revise",IF($AP23="Manuscript revised by Author","Editor to review",IF($AP23="Manuscript finalised by Editor","Evonne to PFP",IF($AP23="Manuscript approved by Evonne","Evelyn to upload to Learnosity",IF($AP23="Manuscript uploaded to Learnosity","Prepress to create Activity",IF($AP23="Ready practice on Learnosity","Prepress to create Activity",IF($AP23="Activity created","Editor to conduct Learnosity review",IF($AP23="Published","Completed",""))))))))) -> Completed
C24: 1.5 Making 9 | D24: PINE_G1_C02_P1.5.1 | E24: Ch 2 Practice 1.5.1: Making a number story for 9 | F24: To make a number story to illustrate a number bond for 9 | G24: 10 | J24: 1.022 To make a number story to illustrate a number bond for 9 M1AL-IIIi-9 | K24: M1AL-IIIi-9 | L24: Identifies and creates patterns to compose and decompose using addition eg 7 = 0 + 7, 1 + 6, 2 + 5, 3 + 4, 4 + 3, 5 + 2, 6 + 1, 7 + 0 | M24: M1AL-IIIi-9: Identifies and creates patterns to compose and decompose using addition. | N24: 1.051 Identifies and creates patterns to compose and decompose M1AL-IIIi-9 | O24: P1/P2/A1/A2 | P24: PH_G1_C02_P1.5.1 | Q24: =E24 -> Ch 2 Practice 1.5.1: Making a number story for 9 | R24: PH, PR1MEPH | S24: Practice | T24: MATHPRO | U24: Grade 1 | V24: Chapter 2 Number Bonds | W24: 9789814969369 | X24: 21 | Y24: 1. Numbers and Number Sense | Z24: G1.1.01 Whole Numbers / Place Value | AA24: Telling number stories | AB24: =J24 -> 1.022 To make a number story to illustrate a number bond for 9 M1AL-IIIi-9 | AC24: =Y24 -> 1. Numbers and Number Sense | AD24: =Z24 -> G1.1.01 Whole Numbers / Place Value | AE24: =K24 -> M1AL-IIIi-9 | AF24: =M24 -> M1AL-IIIi-9: Identifies and creates patterns to compose and decompose using addition. | AG24: =N24 -> 1.051 Identifies and creates patterns to compose and decompose M1AL-IIIi-9 | AH24: 2 | AI24: PH_G1_C01_P1.1.1 | AJ24: To count within 10 (including the use of zero to denote an empty set) | AP24: Published | AQ24: =IF($AP24="Raw Manuscript created","Editor to review",IF($AP24="Manuscript reviewed by Editor","Author to revise",IF($AP24="Manuscript revised by Author","Editor to review",IF($AP24="Manuscript finalised by Editor","Evonne to PFP",IF($AP24="Manuscript approved by Evonne","Evelyn to upload to Learnosity",IF($AP24="Manuscript uploaded to Learnosity","Prepress to create Activity",IF($AP24="Ready practice on Learnosity","Prepress to create Activity",IF($AP24="Activity created","Editor to conduct Learnosity review",IF($AP24="Published","Completed",""))))))))) -> Completed
D25: PINE_G1_C02_P1.5.2 | E25: Ch 2 Practice 1.5.2: Making 9 | F25: To break a set of 9 objects into two parts in different ways | G25: 11 | H25: 6 (Rev1) | J25: 1.023 To break a set of 9 objects into two parts in different ways M1NS-Ic-4 | K25: M1NS-Ic-4 | L25: Composes and decomposes a given number eg 5 is 5 and 0, 4 and 1, 3 and 2, 2 and 3, 1 and 4, 0 and 5 | M25: M1NS-Ic-4: Composes and decomposes a given number. | N25: 1.004 Composes and decomposes a given number M1NS-Ic-4 | O25: P1/P2/A1/A2 | P25: PH_G1_C02_P1.5.2 | Q25: =E25 -> Ch 2 Practice 1.5.2: Making 9 | R25: PH, PR1MEPH | S25: Practice | T25: MATHPRO | U25: Grade 1 | V25: Chapter 2 Number Bonds | W25: 9789814969369 | X25: 21 | Y25: 1. Numbers and Number Sense | Z25: G1.1.01 Whole Numbers / Place Value | AA25: Telling number stories | AB25: =J25 -> 1.023 To break a set of 9 objects into two parts in different ways M1NS-Ic-4 | AC25: =Y25 -> 1. Numbers and Number Sense | AD25: =Z25 -> G1.1.01 Whole Numbers / Place Value | AE25: =K25 -> M1NS-Ic-4 | AF25: =M25 -> M1NS-Ic-4: Composes and decomposes a given number. | AG25: =N25 -> 1.004 Composes and decomposes a given number M1NS-Ic-4 | AH25: 2 | AI25: PH_G1_C02_P1.5.1 | AJ25: To make a number story to illustrate a number bond for 9 | AP25: Published | AQ25: =IF($AP25="Raw Manuscript created","Editor to review",IF($AP25="Manuscript reviewed by Editor","Author to revise",IF($AP25="Manuscript revised by Author","Editor to review",IF($AP25="Manuscript finalised by Editor","Evonne to PFP",IF($AP25="Manuscript approved by Evonne","Evelyn to upload to Learnosity",IF($AP25="Manuscript uploaded to Learnosity","Prepress to create Activity",IF($AP25="Ready practice on Learnosity","Prepress to create Activity",IF($AP25="Activity created","Editor to conduct Learnosity review",IF($AP25="Published","Completed",""))))))))) -> Completed
D26: PINE_G1_C02_P1.5.3 | E26: Ch 2 Practice 1.5.3: Writing number bonds for 9 | F26: To write a number bond for 9 | J26: 1.024 To write a number bond for 9 M1NS-Ic-4 | K26: M1NS-Ic-4 | L26: Composes and decomposes a given number eg 5 is 5 and 0, 4 and 1, 3 and 2, 2 and 3, 1 and 4, 0 and 5 | M26: M1NS-Ic-4: Composes and decomposes a given number. | N26: 1.004 Composes and decomposes a given number M1NS-Ic-4 | O26: P1/P2/A1/A2 | P26: PH_G1_C02_P1.5.3 | Q26: =E26 -> Ch 2 Practice 1.5.3: Writing number bonds for 9 | R26: PH, PR1MEPH | S26: Practice | T26: MATHPRO | U26: Grade 1 | V26: Chapter 2 Number Bonds | W26: 9789814969369 | X26: 21 | Y26: 1. Numbers and Number Sense | Z26: G1.1.01 Whole Numbers / Place Value | AA26: Telling number stories | AB26: =J26 -> 1.024 To write a number bond for 9 M1NS-Ic-4 | AC26: =Y26 -> 1. Numbers and Number Sense | AD26: =Z26 -> G1.1.01 Whole Numbers / Place Value | AE26: =K26 -> M1NS-Ic-4 | AF26: =M26 -> M1NS-Ic-4: Composes and decomposes a given number. | AG26: =N26 -> 1.004 Composes and decomposes a given number M1NS-Ic-4 | AH26: 2 | AI26: PH_G1_C02_P1.5.2 | AJ26: To break a set of 9 objects into two parts in different ways | AP26: Published | AQ26: =IF($AP26="Raw Manuscript created","Editor to review",IF($AP26="Manuscript reviewed by Editor","Author to revise",IF($AP26="Manuscript revised by Author","Editor to review",IF($AP26="Manuscript finalised by Editor","Evonne to PFP",IF($AP26="Manuscript approved by Evonne","Evelyn to upload to Learnosity",IF($AP26="Manuscript uploaded to Learnosity","Prepress to create Activity",IF($AP26="Ready practice on Learnosity","Prepress to create Activity",IF($AP26="Activity created","Editor to conduct Learnosity review",IF($AP26="Published","Completed",""))))))))) -> Completed
